Workbook

Sheet Planilha4
A1: CONTRATOS | B1: 14
A2: INDICE ABERTURA | D2: STOP | E2: PARCIAL 1 | F2: PARCIAL 2 | G2: ALVO FINAL | J2: 46162 | K2: 46163 | L2: 46164 | M2: 46167 | N2: 46169 | O2: 46170 | P2: 46171 | Q2: 46174 | R2: 46175 | S2: 46176
A3: 1 | B3: 46162 | C3: COMPRA | D3: NÃO | E3: OK | F3: OK | G3: OK | H3: 2160 | J3: =H3+H18+H31 -> 2205 | K3: =H4+H19+H32 -> -1635 | L3: =H5+H20+H33 -> 2505 | M3: =H6+H21+H34 -> 2670 | N3: =H7+H22+H35 -> 2505 | O3: =H8+H23+H36 -> -1635 | P3: =H9+H24+H37 -> -1200 | Q3: =H10+H25+H38 -> -1200 | R3: =H11+H26+H39 -> 2505 | S3: =H12+H27+H40 -> 3915 | U3: =SUM(J3:T3) -> 10635
A4: 2 | B4: 46163 | C4: VENDA | D4: OK | E4: NÃO | F4: NÃO | G4: NÃO | H4: -1680
A5: 3 | B5: 46164 | C5: COMPRA | D5: NÃO | E5: OK | F5: NÃO | G5: NÃO | H5: 210
A6: 4 | B6: 46167 | C6: COMPRA | D6: NÃO | E6: OK | F6: OK | G6: NÃO | H6: 810
A7: 5 | B7: 46169 | C7: VENDA | D7: NÃO | E7: OK | F7: NÃO | G7: NÃO | H7: 210
A8: 6 | B8: 46170 | C8: VENDA | D8: OK | E8: NÃO | F8: NÃO | G8: NÃO | H8: -1680
A9: 7 | B9: 46171 | C9: VENDA | D9: NÃO | E9: OK | F9: OK | G9: NÃO | H9: 810
A10: 8 | B10: 46174 | C10: COMPRA | D10: NÃO | E10: OK | F10: OK | G10: NÃO | H10: 810
A11: 9 | B11: 46175 | C11: COMPRA | D11: NÃO | E11: OK | F11: NÃO | G11: NÃO | H11: 210
A12: 10 | B12: 46176 | C12: VENDA | D12: NÃO | E12: OK | F12: OK | G12: OK | H12: 2160
H13: =SUM(H3:H12) -> 4020
A16: CONTRATOS | B16: 18 | D16: STOP | E16: PARCIAL 1 | G16: ALVO FINAL
A17: DOLAR ABERTURA
A18: 1 | B18: 46162 | C18: VENDA | D18: OK | G18: NÃO | H18: =-B16*12*10 -> -2160
A19: 2 | B19: 46163 | C19: COMPRA | D19: OK | G19: NÃO | H19: =-B16*12*10 -> -2160
A20: 3 | B20: 46164 | C20: VENDA | D20: NÃO | E20: OK | H20: =B16*10*0.5 -> 90
A21: 4 | B21: 46167 | C21: VENDA | D21: NÃO | E21: OK | G21: OK | H21: =B16*22*10 -> 3960
A22: 5 | B22: 46169 | C22: COMPRA | D22: NÃO | E22: OK | H22: =B16*10*0.5 -> 90
A23: 6 | B23: 46170 | C23: COMPRA | D23: OK | G23: NÃO | H23: =-B16*10*12 -> -2160
A24: 7 | B24: 46171 | C24: COMPRA | D24: NÃO | E24: OK | G24: NÃO | H24: =B16*10*0.5 -> 90
A25: 8 | B25: 46174 | C25: VENDA | D25: NÃO | E25: OK | G25: NÃO | H25: =B16*10*0.5 -> 90
A26: 9 | B26: 46175 | C26: VENDA | D26: NÃO | E26: OK | G26: NÃO | H26: =B16*10*0.5 -> 90
A27: 10 | B27: 46176 | C27: COMPRA | D27: NÃO | E27: OK | G27: OK | H27: =B16*10*22 -> 3960
H28: =SUM(H18:H27) -> 1890
A29: CONTRATOS | B29: 21
A30: RED DOLAR
A31: 1 | B31: 46162 | C31: COMPRA | D31: NÃO | G31: OK | H31: =B29*10.5*10 -> 2205
A32: 2 | B32: 46163 | C32: COMPRA | D32: NÃO | G32: OK | H32: =B29*10.5*10 -> 2205
A33: 3 | B33: 46164 | C33: COMPRA | D33: NÃO | G33: OK | H33: =B29*10.5*10 -> 2205
A34: 4 | B34: 46167 | C34: COMPRA | D34: OK | G34: NÃO | H34: =-B29*10*10 -> -2100
A35: 5 | B35: 46169 | C35: VENDA | D35: NÃO | G35: OK | H35: =B29*10.5*10 -> 2205
A36: 6 | B36: 46170 | C36: VENDA | D36: NÃO | G36: OK | H36: =B29*10.5*10 -> 2205
A37: 7 | B37: 46171 | C37: VENDA | D37: OK | G37: NÃO | H37: =-B29*10*10 -> -2100
A38: 8 | B38: 46174 | C38: COMPRA | D38: OK | G38: NÃO | H38: =-B29*10*10 -> -2100
A39: 9 | B39: 46175 | C39: COMPRA | D39: NÃO | G39: OK | H39: =B29*10.5*10 -> 2205
A40: 10 | B40: 46176 | C40: VENDA | D40: OK | G40: NÃO | H40: =-B29*10.5*10 -> -2205
H41: =SUM(H31:H40) -> 4725
H45: =H13+H28+H41 -> 10635

Sheet ABERTURA INDICE
A2: CONTRATOS | B2: 21
A3: INDICE ABERTURA | D3: STOP | E3: PARCIAL 1 | F3: PARCIAL 2 | G3: ALVO FINAL | K3: =H25/19 -> 618.94737
A5: 1 | B5: 46085 | C5: COMPRA | D5: NÃO | E5: OK | F5: OK | G5: OK | H5: 4130
A6: 2 | B6: 46086 | C6: COMPRA | D6: OK | E6: NÃO | F6: NÃO | G6: NÃO | H6: -2520
A7: 3 | B7: 46087 | C7: VENDA | D7: OK | E7: NÃO | F7: NÃO | G7: NÃO | H7: -2520
A8: 4 | B8: 46090 | C8: VENDA | D8: OK | E8: NÃO | F8: NÃO | G8: NÃO | H8: -2520
A9: 5 | B9: 46091 | C9: COMPRA | D9: NÃO | E9: OK | F9: OK | G9: NÃO | H9: 910
A10: 6 | B10: 46092 | C10: COMPRA | D10: NÃO | E10: OK | F10: NÃO | G10: NÃO | H10: 280
A11: 7 | B11: 46093 | C11: VENDA | D11: NÃO | E11: OK | F11: OK | G11: OK | H11: 4130
A12: 8 | B12: 46094 | C12: VENDA | D12: NÃO | E12: OK | F12: OK | G12: NÃO | H12: 910
A13: 9 | B13: 16//03/2026 | C13: COMPRA | D13: NÃO | E13: OK | F13: OK | G13: NÃO | H13: 910
A14: 10 | B14: 46099 | C14: COMPRA | D14: OK | E14: NÃO | F14: NÃO | G14: NÃO | H14: -2520
A15: 11 | B15: 46100 | C15: VENDA | D15: NÃO | E15: OK | F15: OK | G15: NÃO | H15: 910
A16: 12 | B16: 46101 | C16: VENDA | D16: NÃO | E16: OK | F16: NÃO | G16: NÃO | H16: 280
A17: 13 | B17: 46104 | C17: VENDA | D17: NÃO | E17: OK | F17: OK | G17: NÃO | H17: 910
A18: 14 | B18: 46105 | C18: VENDA | D18: NÃO | E18: OK | F18: OK | G18: OK | H18: 4130
A19: 15 | B19: 46106 | C19: COMPRA | D19: NÃO | E19: OK | F19: OK | G19: NÃO | H19: 910
A20: 16 | B20: 46107 | C20: VENDA | D20: NÃO | E20: OK | F20: OK | G20: NÃO | H20: 910
A21: 17 | B21: 46108 | C21: VENDA | D21: NÃO | E21: OK | F21: OK | G21: NÃO | H21: 910
A22: 18 | B22: 46111 | C22: COMPRA | D22: OK | E22: NÃO | F22: NÃO | G22: NÃO | H22: -2520
A23: 19 | B23: 46112 | C23: COMPRA | D23: NÃO | E23: OK | F23: OK | G23: OK | H23: 4130
H25: =SUM(H5:H23) -> 11760
D27: STOP | E27: PARCIAL 1 | F27: PARCIAL 2 | G27: ALVO FINAL | J27: =H48/20 -> 213.5
A28: 1 | B28: 46113 | C28: COMPRA | D28: NÃO | E28: OK | F28: NÃO | G28: NÃO | H28: 280
A29: 2 | B29: 46114 | C29: VENDA | D29: NÃO | E29: OK | F29: OK | G29: NÃO | H29: 910
A30: 3 | B30: 46118 | C30: COMPRA | D30: NÃO | E30: OK | F30: OK | G30: NÃO | H30: 910
A31: 4 | B31: 46119 | C31: COMPRA | D31: NÃO | E31: OK | F31: OK | G31: NÃO | H31: 910
A32: 5 | B32: 46120 | C32: COMPRA | D32: NÃO | E32: OK | F32: OK | G32: NÃO | H32: 910
A33: 6 | B33: 46121 | C33: VENDA | D33: INABILITADO
A34: 7 | B34: 46122 | C34: COMPRA | D34: NÃO | E34: OK | F34: OK | G34: NÃO | H34: 910
A35: 8 | B35: 46125 | C35: VENDA | D35: NÃO | E35: OK | F35: OK | G35: NÃO | H35: 910
A36: 9 | B36: 46126 | C36: COMPRA | D36: NÃO | E36: OK | F36: OK | G36: NÃO | H36: 910
A37: 10 | B37: 46127 | C37: COMPRA | D37: INABILITADO
A38: 11 | B38: 46128 | C38: COMPRA | D38: INABILITADO
A39: 12 | B39: 46129 | C39: COMPRA | D39: NÃO | E39: OK | F39: OK | G39: NÃO | H39: 910
A40: 13 | B40: 46132 | C40: VENDA | D40: NÃO | E40: OK | F40: NÃO | G40: NÃO | H40: 280
A41: 14 | B41: 46134 | C41: COMPRA | D41: OK | E41: NÃO | F41: NÃO | G41: NÃO | H41: -2520
A42: 15 | B42: 46135 | C42: VENDA | D42: NÃO | E42: OK | F42: NÃO | G42: NÃO | H42: 280
A43: 16 | B43: 46136 | C43: VENDA | D43: INABILITADO
A44: 17 | B44: 46139 | C44: COMPRA | D44: NÃO | E44: OK | F44: NÃO | G44: NÃO | H44: 280
...

Sheet DOLAR ABERTURA
A1: ABERTURA DOLAR
D2: STOP | E2: 0X0 | F2: ALVO FINAL
B3: 46085 | C3: VENDA | D3: NÃO | E3: OK | F3: OK | G3: 3300
B4: 46086 | C4: VENDA | D4: OK | E4: NÃO | F4: NÃO | G4: -1800
B5: 46087 | C5: COMPRA | D5: OK | E5: NÃO | F5: NÃO | G5: -1800
B6: 46090 | C6: COMPRA | D6: OK | E6: NÃO | F6: NÃO | G6: -1800
B7: 46091 | C7: VENDA | D7: OK | E7: NÃO | F7: OK | G7: -1800
B8: 46092 | C8: VENDA | D8: NÃO | E8: OK | F8: NÃO | G8: 75
B9: 46093 | C9: COMPRA | D9: NÃO | E9: OK | F9: NÃO | G9: 75
B10: 46094 | C10: COMPRA | D10: OK | E10: NÃO | F10: NÃO | G10: -1800
B11: 46097 | C11: VENDA | D11: NÃO | E11: OK | F11: OK | G11: 3300
B12: 46099 | C12: VENDA | D12: NÃO | E12: OK | F12: NÃO | G12: 75
B13: 46100 | C13: VENDA | D13: OK | E13: NÃO | F13: NÃO | G13: -1800
B14: 46101 | C14: COMPRA | D14: OK | E14: NÃO | F14: NÃO | G14: -1800
... B21: 46112 | C21: VENDA | D21: NÃO | E21: OK | F21: NÃO | G21: 75
G23: =SUM(G3:G22) -> -2550
D25: STOP | E25: 0X0 | F25: ALVO FINAL
B26: 46113 | C26: VENDA | D26: OK | E26: NÃO | F26: NÃO | G26: -1800
B27: 46114 | C27: COMPRA | D27: OK | E27: NÃO | F27: NÃO | G27: -1800
B28: 46118 | C28: VENDA | D28: OK | E28: NÃO | F28: NÃO | G28: -1800
B29: 46119 | C29: VENDA | D29: OK | E29: NÃO | F29: NÃO | G29: -1800
B30: 46120 | C30: VENDA | D30: NÃO | E30: OK | F30: OK | G30: 3300
B31: 46122 | C31: VENDA | D31: NÃO | E31: OK | F31: OK | G31: 3300
B32: 46125 | C32: COMPRA | D32: NÃO | E32: OK | F32: NÃO | G32: 75
B33: 46126 | C33: VENDA | D33: OK | E33: NÃO | F33: NÃO | G33: -1800
B34: 46129 | C34: VENDA | D34: NÃO | E34: OK | F34: OK | G34: 3300
B35: 46132 | C35: COMPRA | D35: NÃO | E35: OK | F35: NÃO | G35: 75
B36: 46134 | C36: VENDA | D36: OK | E36: NÃO | F36: NÃO | G36: -1800
B37: 46135 | C37: COMPRA | D37: OK | E37: NÃO | F37: NÃO | G37: -1800
... B40: 46141 | C40: VENDA | D40: OK | E40: NÃO | F40: NÃO | G40: -1800
G42: =SUM(G26:G41) -> -4200
D44: STOP | E44: 0X0 | F44: ALVO FINAL
B45: 46146 | C45: VENDA | D45: NÃO | E45: OK | F45: NÃO | G45: 75
B46: 46147 | C46: VENDA | D46: NÃO | E46: OK | F46: O | G46: 3300
B47: 46148 | C47: VENDA | D47: OK | E47: NÃO | F47: NÃO | G47: -1800
B48: 46149 | C48: INABILITADO
B49: 46150 | C49: VENDA | D49: NÃO | E49: OK | F49: OK | G49: 3300
B50: 46153 | C50: VENDA | D50: NÃO | E50: OK | F50: NÃO | G50: 75
B51: 46154 | C51: COMPRA | D51: OK | E51: NÃO | F51: NÃO | G51: -1800
B52: 46155 | C52: VENDA | D52: OK | E52: NÃO | F52: NÃO | G52: -1800
...

Sheet DOLAR RED
D2: STOP | E2: ALVO FINAL
A3: 1 | B3: 46085 | C3: COMPRA | D3: NÃO | E3: OK | F3: 2205
A4: 2 | B4: 46086 | C4: VENDA | D4: NÃO | E4: OK | F4: 2205
A5: 3 | B5: 46087 | C5: COMPRA | D5: OK | E5: NÃO | F5: -2100
A6: 4 | B6: 46090 | C6: COMPRA | D6: OK | E6: NÃO | F6: -2100
A7: 5 | B7: 46091 | C7: VENDA | D7: OK | E7: NÃO | F7: -2100
A8: 6 | B8: 46092 | C8: COMPRA | D8: NÃO | E8: OK | F8: 2205
A9: 7 | B9: 46093 | C9: VENDA | D9: OK | E9: NÃO | F9: -2100
A10: 8 | B10: 46094 | C10: COMPRA | D10: NÃO | E10: OK | F10: 2205
A11: 9 | B11: 46097 | C11: COMPRA | D11: NÃO | E11: OK | F11: 2205
A12: 10 | B12: 46099 | C12: VENDA | D12: OK | E12: NÃO | F12: -2100
A13: 11 | B13: 46100 | C13: VENDA | D13: OK | E13: NÃO | F13: -2100
A14: 12 | B14: 46101 | C14: COMPRA | D14: NÃO | E14: OK | F14: 2205
... A21: 19 | B21: 46112 | C21: VENDA | D21: NÃO | E21: OK | F21: 2205
F23: =SUM(F3:F22) -> 7455
D24: STOP | E24: ALVO FINAL
A25: 1 | B25: 46113 | C25: COMPRA | D25: NÃO | E25: OK | F25: 2205
A26: 2 | B26: 46114 | C26: COMPRA | D26: OK | E26: NÃO | F26: -2100
A27: 3 | B27: 46118 | C27: VENDA | D27: NÃO | E27: OK | F27: 2205
A28: 4 | B28: 46119 | C28: VENDA | D28: NÃO | E28: OK | F28: 2205
A29: 5 | B29: 46120 | C29: COMPRA | D29: NÃO | E29: OK | F29: 2205
A30: 6 | B30: 46121 | C30: VENDA | D30: NÃO | E30: OK | F30: 2205
A31: 7 | B31: 46122 | C31: COMPRA | D31: OK | E31: NÃO | F31: -2100
A32: 8 | B32: 46125 | C32: COMPRA | D32: OK | E32: NÃO | F32: -2100
A33: 9 | B33: 46126 | C33: VENDA | D33: NÃO | E33: OK | F33: 2205
A34: 10 | B34: 46127 | C34: VENDA | D34: NÃO | E34: OK | F34: 2205
A35: 11 | B35: 46128 | C35: COMPRA | D35: NÃO | E35: OK | F35: 2205
A36: 12 | B36: 46129 | C36: COMPRA | D36: OK | E36: NÃO | F36: -2100
... A44: 20 | B44: 46142 | C44: COMPRA | D44: NÃO | E44: OK | F44: 2205
F46: =SUM(F25:F45) -> 22575
D48: STOP | E48: ALVO FINAL
A49: 1 | B49: 46146 | C49: VENDA | D49: NÃO | E49: OK | F49: 2205
A50: 2 | B50: 46147 | C50: VENDA | D50: NÃO | E50: OK | F50: 2205
A51: 3 | B51: 46148 | C51: VENDA | D51: NÃO | E51: OK | F51: 2205
A52: 4 | B52: 46149 | C52: VENDA | D52: NÃO | E52: OK | F52: 2205
A53: 5 | B53: 46150 | C53: COMPRRA | D53: OK | E53: NÃO | F53: -2100
A54: 6 | B54: 46153 | C54: VENDA | D54: NÃO | E54: OK | F54: 2205
A55: 7 | B55: 46154 | C55: VENDA | D55: NÃO | E55: OK | F55: 2205
A56: 8 | B56: 46155 | C56: VENDA | D56: OK | E56: NÃO | F56: -2100
A57: 9 | B57: 46156 | C57: COMPRRA | D57: OK | E57: NÃO | F57: -2100
...

Sheet DI ABERTURA
A1: ABERTURA DOLAR | D1: CONTRATOS | E1: 14
D2: STOP | E2: 0X0 | F2: ALVO FINAL
B3: 46085 | C3: VENDA | D3: OK | F3: NÃO | G3: -1036.76
B4: 46086 | C4: VENDA | D4: OK | F4: NÃO | G4: -1036.76
B5: 46087 | C5: COMPRA | D5: NÃO | F5: OK | G5: 1494.96
B6: 46090 | C6: COMPRA | D6: NÃO | F6: OK | G6: 1494.96
B7: 46091 | C7: VENDA | D7: NÃO | F7: OK | G7: 1494.96
B8: 46092 | C8: VENDA | D8: OK | F8: NÃO | G8: -1036.76
B9: 46093 | C9: COMPRA | D9: NÃO | F9: OK | G9: 1494.96
B10: 46094 | C10: COMPRA | D10: NÃO | F10: OK | G10: 1494.96
B11: 46097 | C11: VENDA | D11: NÃO | F11: OK | G11: 1494.96
B12: 46099 | C12: VENDA | D12: OK | F12: NÃO | G12: -1036.76
B13: 46100 | C13: VENDA | D13: NÃO | F13: OK | G13: 1494.96
B14: 46101 | C14: COMPRA | D14: NÃO | F14: OK | G14: 1494.96
... B21: 46112 | C21: VENDA | D21: NÃO | F21: OK | G21: 1494.96
G23: =SUM(G3:G22) -> 13213.92
D25: STOP | E25: 0X0 | F25: ALVO FINAL
A26: 1 | B26: 46113 | C26: VENDA | D26: NÃO | F26: OK | G26: 1494.96
A27: 2 | B27: 46114 | C27: COMPRA | D27: OK | F27: NÃO | G27: -1036.76
A28: 3 | B28: 46118 | C28: VENDA | D28: OK | F28: NÃO | G28: -1036.76
A29: 4 | B29: 46119 | C29: VENDA | D29: OK | F29: NÃO | G29: -1036.76
A30: 5 | B30: 46120 | C30: VENDA | D30: NÃO | F30: OK | G30: 1494.96
A31: 6 | B31: 46121 | C31: COMPRA | D31: NÃO | F31: OK | G31: 1494.96
A32: 7 | B32: 46122 | C32: VENDA | D32: OK | F32: NÃO | G32: -1036.76
A33: 8 | B33: 46125 | C33: COMPRA | D33: NÃO | F33: OK | G33: 1494.96
A34: 9 | B34: 46126 | C34: VENDA | D34: NÃO | F34: OK | G34: 1494.96
A35: 10 | B35: 46127 | C35: VENDA | D35: OK | F35: NÃO | G35: -1036.76
A36: 11 | B36: 46128 | C36: VENDA | D36: OK | F36: NÃO | G36: -1036.76
A37: 12 | B37: 46129 | C37: VENDA | D37: OK | F37: NÃO | G37: -1036.76
... A45: 20 | B45: 46142 | C45: VENDA | D45: NÃO | F45: OK | G45: 1494.96
G47: =SUM(G26:G46) -> -481.44
D49: STOP | E49: ALVO FINAL
A50: 1 | B50: 46146 | C50: VENDA | D50: OK | E50: NÃO | G50: -1036.76
A51: 2 | B51: 46147 | C51: VENDA | D51: OK | E51: NÃO | G51: -1036.76
A52: 3 | B52: 46148 | C52: VENDA | D52: OK | E52: NÃO | G52: -1036.76
A53: 4 | B53: 46149 | C53: INABILITADO
A54: 5 | B54: 46150 | C54: VENDA | D54: NÃO | E54: OK | G54: 1494.96
A55: 6 | B55: 46153 | C55: VENDA | D55: OK | E55: NÃO | G55: -1036.76
A56: 7 | B56: 46154 | C56: COMPRA | D56: NÃO | E56: OK | G56: 1494.96
A57: 8 | B57: 46155 | C57: VENDA | D57: OK | E57: NÃO | G57: -1036.76
...

Sheet RELATORO PERFORMACE
B1: RESUMO DE MARÇO
B2: ABERTURA INDICE | D2: ='ABERTURA INDICE'!H25 -> 11760
B3: ABERTURA DOLAR | D3: ='DOLAR ABERTURA'!G23 -> -2550
B4: RED DOLAR | D4: ='DOLAR RED'!F23 -> 7455
B5: ABERTURA DI | D5: ='DI ABERTURA'!G23 -> 13213.92
D6: =SUM(D2:D5) -> 29878.92
B8: RESUMO DE MARÇO
A9: 1 | B9: 46085 | C9: ='ABERTURA INDICE'!H5+'DOLAR ABERTURA'!G3+'DOLAR RED'!F3+'DI ABERTURA'!G3 -> 8598.24 | D9: =C9 -> 8598.24
A10: 2 | B10: 46086 | C10: ='ABERTURA INDICE'!H6+'DOLAR ABERTURA'!G4+'DOLAR RED'!F4+'DI ABERTURA'!G4 -> -3151.76 | D10: =D9+C10 -> 5446.48
A11: 3 | B11: 46087 | C11: ='ABERTURA INDICE'!H7+'DOLAR ABERTURA'!G5+'DOLAR RED'!F5+'DI ABERTURA'!G5 -> -4925.04 | D11: =D10+C11 -> 521.44
A12: 4 | B12: 46090 | C12: ='ABERTURA INDICE'!H8+'DOLAR ABERTURA'!G6+'DOLAR RED'!F6+'DI ABERTURA'!G6 -> -4925.04 | D12: =D11+C12 -> -4403.6
A13: 5 | B13: 46091 | C13: ='ABERTURA INDICE'!H9+'DOLAR ABERTURA'!G7+'DOLAR RED'!F7+'DI ABERTURA'!G7 -> -1495.04 | D13: =D12+C13 -> -5898.64
A14: 6 | B14: 46092 | C14: ='ABERTURA INDICE'!H10+'DOLAR ABERTURA'!G8+'DOLAR RED'!F8+'DI ABERTURA'!G8 -> 1523.24 | D14: =D13+C14 -> -4375.4
A15: 7 | B15: 46093 | C15: ='ABERTURA INDICE'!H11+'DOLAR ABERTURA'!G9+'DOLAR RED'!F9 -> 2105 | D15: =D14+C15 -> -2270.4
A16: 8 | B16: 46094 | C16: ='ABERTURA INDICE'!H12+'DOLAR ABERTURA'!G10+'DOLAR RED'!F10+'DI ABERTURA'!G9 -> 2809.96 | D16: =D15+C16 -> 539.56
A17: 9 | B17: 16//03/2026 | C17: ='ABERTURA INDICE'!H13+'DOLAR ABERTURA'!G11+'DOLAR RED'!F11+'DI ABERTURA'!G11 -> 7909.96 | D17: =D16+C17 -> 8449.52
A18: 10 | B18: 46099 | C18: ='ABERTURA INDICE'!H14+'DOLAR ABERTURA'!G12+'DOLAR RED'!F12+'DI ABERTURA'!G12 -> -5581.76 | D18: =D17+C18 -> 2867.76
A19: 11 | B19: 46100 | C19: ='ABERTURA INDICE'!H15+'DOLAR ABERTURA'!G13+'DOLAR RED'!F13+'DI ABERTURA'!G13 -> -1495.04 | D19: =D18+C19 -> 1372.72
A20: 12 | B20: 46101 | C20: ='ABERTURA INDICE'!H16+'DOLAR ABERTURA'!G14+'DOLAR RED'!F14+'DI ABERTURA'!G14 -> 2179.96 | D20: =D19+C20 -> 3552.68
A21: 13 | B21: 46104 | C21: ='ABERTURA INDICE'!H17+'DOLAR ABERTURA'!G15+'DOLAR RED'!F15+'DI ABERTURA'!G15 -> 5378.24 | D21: =D20+C21 -> 8930.92
A22: 14 | B22: 46105 | C22: ='ABERTURA INDICE'!H18+'DOLAR ABERTURA'!G16+'DOLAR RED'!F16+'DI ABERTURA'!G16 -> 6824.96 | D22: =D21+C22 -> 15755.88
A23: 15 | B23: 46106 | C23: ='ABERTURA INDICE'!H19+'DOLAR ABERTURA'!G17+'DOLAR RED'!F17+'DI ABERTURA'!G17 -> -4026.76 | D23: =D22+C23 -> 11729.12
A24: 16 | B24: 46107 | C24: ='ABERTURA INDICE'!H20+'DOLAR ABERTURA'!G18+'DOLAR RED'!F18+'DI ABERTURA'!G18 -> 4684.96 | D24: =D23+C24 -> 16414.08
A25: 17 | B25: 46108 | C25: ='ABERTURA INDICE'!H21+'DOLAR ABERTURA'!G19+'DOLAR RED'!F19+'DI ABERTURA'!G19 -> 4684.96 | D25: =D24+C25 -> 21099.04
A26: 18 | B26: 46111 | C26: ='ABERTURA INDICE'!H22+'DOLAR ABERTURA'!G20+'DOLAR RED'!F20+'DI ABERTURA'!G20 -> -620.04 | D26: =D25+C26 -> 20479
A27: 19 | B27: 46112 | C27: ='ABERTURA INDICE'!H23+'DOLAR ABERTURA'!G21+'DOLAR RED'!F21+'DI ABERTURA'!G21 -> 7904.96 | D27: =D26+C27 -> 28383.96
C28: =SUM(C9:C27) -> 28383.96
B30: RESUMO DE ABRIL
B31: ABERTURA INDICE | D31: ='ABERTURA INDICE'!H48 -> 4270
B32: ABERTURA DOLAR | D32: ='DOLAR ABERTURA'!G42 -> -4200
B33: RED DOLAR | D33: ='DOLAR RED'!F46 -> 22575
B34: ABERTURA DI | D34: ='DI ABERTURA'!G47 -> -481.44
D35: =SUM(D31:D34) -> 22163.56
B36: RESUMO DE ABRIL
B37: 1 | C37: 46113 | D37: ='ABERTURA INDICE'!H28+'DOLAR ABERTURA'!G26+'DOLAR RED'!F25+'DI ABERTURA'!G26 -> 2179.96 | E37: =D37 -> 2179.96
B38: 2 | C38: 46114 | D38: ='ABERTURA INDICE'!H29+'DOLAR ABERTURA'!G27+'DOLAR RED'!F26+'DI ABERTURA'!G27 -> -4026.76 | E38: =E37+D38 -> -1846.8
B39: 3 | C39: 46118 | D39: ='ABERTURA INDICE'!H30+'DOLAR ABERTURA'!G28+'DOLAR RED'!F27+'DI ABERTURA'!G28 -> 278.24 | E39: =E38+D39 -> -1568.56
B40: 4 | C40: 46119 | D40: ='ABERTURA INDICE'!H31+'DOLAR ABERTURA'!G29+'DOLAR RED'!F28+'DI ABERTURA'!G29 -> 278.24 | E40: =E39+D40 -> -1290.32
B41: 5 | C41: 46120 | D41: ='ABERTURA INDICE'!H32+'DOLAR ABERTURA'!G30+'DOLAR RED'!F29+'DI ABERTURA'!G30 -> 7909.96 | E41: =E40+D41 -> 6619.64
B42: 6 | C42: 46121 | D42: ='DOLAR RED'!F30+'DI ABERTURA'!G31 -> 3699.96 | E42: =E41+D42 -> 10319.6
...
